<?xml version="1.0"?>
<sdf version="1.7">

    <world name="my_world">
        <model name="water_plane"> 
            <static>true</static>
            <link name="link">
                <visual name="water plane">
                    <geometry>
                        <plane>
                            <size>100 100</size>
                            <normal>0 0 1</normal>
                        </plane>
                    </geometry>
                    <material>
                        <ambient>0 0 1 0.7</ambient>
                        <diffuse>0 0 1 0.7</diffuse>
                        <specular>0 0 1 0.7</specular>
                    </material>
                </visual>
            </link>
        </model>
        <model name="red_sphere">
            <pose>2 0 0.3 0 0 0</pose>
            <static>true</static>
            <link name="link">
                <visual name="visual">
                    <geometry>
                        <sphere>
                            <radius>0.2</radius>
                        </sphere>
                    </geometry>
                    <material>
                        <ambient>1 0 0 1</ambient>
                        <diffuse>1 0 0 1</diffuse>
                        <specular>1 0 0 1</specular>
                    </material>
                </visual>
                <collision name="collision">
                    <geometry>
                        <sphere>
                            <radius>0.2</radius>
                        </sphere>
                    </geometry>
                </collision>
                <inertial>
                    <mass>1.0</mass>
                    <inertia>
                        <ixx>0.001</ixx>
                        <ixy>0.0</ixy>
                        <ixz>0.0</ixz>
                        <iyy>0.001</iyy>
                        <iyz>0.0</iyz>
                        <izz>0.001</izz>
                    </inertia>
                </inertial>
            </link>
        </model>


        <model name="red_sphere2">
            <pose>5 -5 0.3 0 0 0</pose>
            <static>true</static>
            <link name="link">
                <visual name="visual">
                    <geometry>
                        <sphere>
                            <radius>0.2</radius>
                        </sphere>
                    </geometry>
                    <material>
                        <ambient>1 0 0 1</ambient>
                        <diffuse>1 0 0 1</diffuse>
                        <specular>1 0 0 1</specular>
                    </material>
                </visual>
                <collision name="collision">
                    <geometry>
                        <sphere>
                            <radius>0.4</radius>
                        </sphere>
                    </geometry>
                </collision>
                <inertial>
                    <mass>1.0</mass>
                    <inertia>
                        <ixx>0.001</ixx>
                        <ixy>0.0</ixy>
                        <ixz>0.0</ixz>
                        <iyy>0.001</iyy>
                        <iyz>0.0</iyz>
                        <izz>0.001</izz>
                    </inertia>
                </inertial>
            </link>
        </model>

        <model name="red_sphere3">
            <pose>2 5 0.3 0 0 0</pose>
            <static>true</static>
            <link name="link">
                <visual name="visual">
                    <geometry>
                        <sphere>
                            <radius>0.2</radius>
                        </sphere>
                    </geometry>
                    <material>
                        <ambient>1 0 0 1</ambient>
                        <diffuse>1 0 0 1</diffuse>
                        <specular>1 0 0 1</specular>
                    </material>
                </visual>
                <collision name="collision">
                    <geometry>
                        <sphere>
                            <radius>0.4</radius>
                        </sphere>
                    </geometry>
                </collision>
                <inertial>
                    <mass>1.0</mass>
                    <inertia>
                        <ixx>0.001</ixx>
                        <ixy>0.0</ixy>
                        <ixz>0.0</ixz>
                        <iyy>0.001</iyy>
                        <iyz>0.0</iyz>
                        <izz>0.001</izz>
                    </inertia>
                </inertial>
            </link>
        </model>
                



       <model name="red_sphere4">
            <pose>4 4 0.3 0 0 0</pose>
            <static>true</static>
            <link name="link">
                <visual name="visual">
                    <geometry>
                        <sphere>
                            <radius>0.2</radius>
                        </sphere>
                    </geometry>
                    <material>
                        <ambient>1 0 0 1</ambient>
                        <diffuse>1 0 0 1</diffuse>
                        <specular>1 0 0 1</specular>
                    </material>
                </visual>
                <collision name="collision">
                    <geometry>
                        <sphere>
                            <radius>0.4</radius>
                        </sphere>
                    </geometry>
                </collision>
                <inertial>
                    <mass>1.0</mass>
                    <inertia>
                        <ixx>0.001</ixx>
                        <ixy>0.0</ixy>
                        <ixz>0.0</ixz>
                        <iyy>0.001</iyy>
                        <iyz>0.0</iyz>
                        <izz>0.001</izz>
                    </inertia>
                </inertial>
            </link>
        </model>




        <model name="red_sphere5">
            <pose>8 -3 0.3 0 0 0</pose>
            <static>true</static>
            <link name="link">
                <visual name="visual">
                    <geometry>
                        <sphere>
                            <radius>0.2</radius>
                        </sphere>
                    </geometry>
                    <material>
                        <ambient>1 0 0 1</ambient>
                        <diffuse>1 0 0 1</diffuse>
                        <specular>1 0 0 1</specular>
                    </material>
                </visual>
                <collision name="collision">
                    <geometry>
                        <sphere>
                            <radius>0.4</radius>
                        </sphere>
                    </geometry>
                </collision>
                <inertial>
                    <mass>1.0</mass>
                    <inertia>
                        <ixx>0.001</ixx>
                        <ixy>0.0</ixy>
                        <ixz>0.0</ixz>
                        <iyy>0.001</iyy>
                        <iyz>0.0</iyz>
                        <izz>0.001</izz>
                    </inertia>
                </inertial>
            </link>
        </model>



        <scene>
            <ambient>0.0 1.0 1.0</ambient>
            <background>0 0.7 0.8</background>
        </scene>

        <light type="directional" name="sun">
            <cast_shadows>true</cast_shadows>
            <pose>0 0 10 0 0 0</pose>
            <diffuse>1 1 1 1</diffuse>
            <specular>0.5 0.5 0.5 1</specular>
            <attenuation>
              <range>1000</range>
              <constant>0.9</constant>
              <linear>0.01</linear>
              <quadratic>0.001</quadratic>
            </attenuation>
            <direction>-0.5 0.1 -0.9</direction>
          </light>        

        <physics name="1ms" type="ode">
            <max_step_size>0.001</max_step_size>
            <real_time_factor>1.0</real_time_factor>
        </physics>
        <plugin
            filename="ignition-gazebo-physics-system"
            name="ignition::gazebo::systems::Physics">
        </plugin>
        <plugin
            filename="ignition-gazebo-user-commands-system"
            name="ignition::gazebo::systems::UserCommands">
        </plugin>
        <plugin
            filename="ignition-gazebo-scene-broadcaster-system"
            name="ignition::gazebo::systems::SceneBroadcaster">
        </plugin>
        <plugin
            filename="ignition-gazebo-buoyancy-system"
            name="ignition::gazebo::systems::Buoyancy">
            <uniform_fluid_density>1000</uniform_fluid_density>
            <!-- <graded_buoyancy>
                <default_density>1000</default_density>
                <density_change>
                    <above_depth>0</above_depth> 
                    <density>1</density>
                </density_change>
            </graded_buoyancy> -->
        </plugin>

        <model name="box_usv">
            <link name="base_link">
                <collision name="collision">
                    <geometry>
                        <box>
                            <size>1 0.9 0.23</size>
                        </box>
                    </geometry>
                </collision>
                <visual name="visual">
                    <geometry>
                        <box>
                            <size>1 0.9 0.23</size>
                        </box>
                    </geometry>
                </visual>
                <inertial>
                    <pose>0.0012 0 -0.05 0 0 0</pose> 
                    <!-- Adjusted mass to match displaced water volume and
                         prevent the vessel from rising uncontrollably -->
                    <mass>207</mass>
                    <inertia>
                        <ixx>4.1054</ixx>
                        <ixy>0</ixy>
                        <ixz>0</ixz>
                        <iyy>4.8811</iyy>
                        <iyz>0</iyz>
                        <izz>6.8144</izz>
                    </inertia>
                </inertial>
            </link>

            <link name="camera_link">
                <pose>0.002 0 0.6 0 0 0</pose>

                <sensor name="camera_sensor" type="camera">
                    <camera>
                    <horizontal_fov>1.047</horizontal_fov>
                    <image>
                        <width>640</width>
                        <height>480</height>
                        <format>R8G8B8</format>
                    </image>
                    <clip>
                        <near>0.1</near>
                        <far>100</far>
                    </clip>
                    </camera>
                    <always_on>true</always_on>
                    <update_rate>30</update_rate>
                    <visualize>true</visualize>
                </sensor>
            </link>



            <!-- thruster_L link -->
            <link name="thruster_L">
                <pose>-0.525 -0.15 0 0 1.57 0</pose>
                <collision name="collision">
                    <geometry>
                        <box>
                            <size>0.1 0.07 0.05</size>
                        </box>
                    </geometry>
                </collision>
                <visual name="visual">
                    <geometry>
                        <box>
                            <size>0.1 0.07 0.05</size>
                        </box>
                    </geometry>
                    <material>
                        <ambient>0.5 0.5 0.5 1</ambient>
                        <diffuse>0.5 0.5 0.5 1</diffuse>
                        <specular>0.5 0.5 0.5 1</specular>
                    </material>
                </visual>
                <inertial>
                    <mass>0.525</mass>
                    <inertia>
                        <ixx>0.00032375</ixx>
                        <ixy>0</ixy>
                        <ixz>0</ixz>
                        <iyy>0.0018594</iyy>
                        <iyz>0</iyz>
                        <izz>0.0019644</izz>
                    </inertia>
                </inertial>
            </link>

            <!-- thruster_L <-> base_link joint -->
            <joint name="joint_propeller_port_L" type="revolute">
                <pose>0 0 0 0 0 0</pose>
                <parent>base_link</parent>
                <child>thruster_L</child>
                <axis>
                    <xyz>0 0 1</xyz>
                </axis>
            </joint>

            <!-- thruster_R link -->
            <link name="thruster_R">
                <pose>-0.525 0.15 0 0 1.57 0</pose>
                <collision name="collision">
                    <geometry>
                        <box>
                            <size>0.1 0.07 0.05</size>
                        </box>
                    </geometry>
                </collision>
                <visual name="visual">
                    <geometry>
                        <box>
                            <size>0.1 0.07 0.05</size>
                        </box>
                    </geometry>
                    <material>
                        <ambient>0.5 0.5 0.5 1</ambient>
                        <diffuse>0.5 0.5 0.5 1</diffuse>
                        <specular>0.5 0.5 0.5 1</specular>
                    </material>
                </visual>
                <inertial>
                    <mass>0.525</mass>
                    <inertia>
                        <ixx>0.00032375</ixx>
                        <ixy>0</ixy>
                        <ixz>0</ixz>
                        <iyy>0.0018594</iyy>
                        <iyz>0</iyz>
                        <izz>0.0019644</izz>
                    </inertia>
                </inertial>

            </link>
            <!-- thruster_R <-> base_link joint -->
            <joint name="joint_propeller_port_R" type="revolute">
                <pose>0 0 0 0 0 0</pose>
                <parent>base_link</parent>
                <child>thruster_R</child>
                <axis>
                    <xyz>0 0 1</xyz>
                </axis>
            </joint>


            <joint name="camera_joint" type="fixed">
                <parent>base_link</parent>
                <child>camera_link</child>
            </joint>







                        <!-- Hydrodynamics plugin -->
            <plugin
                filename="ignition-gazebo-hydrodynamics-system"
                name="ignition::gazebo::systems::Hydrodynamics">
                <link_name>base_link</link_name>
                <xDotU>-0.04876161</xDotU>
                <yDotV>-1.26324739</yDotV>
                <zDotW>-1.26324739</zDotW>
                <kDotP>0</kDotP>
                <mDotQ>-0.3346</mDotQ>
                <nDotR>-0.3346</nDotR>
                <xUabsU>-0.62282</xUabsU>
                <xU>-5</xU>
                <yVabsV>-60.127</yVabsV>
                <yV>-5</yV>
                <zWabsW>-6.0127</zWabsW>
                <zW>-100</zW>
                <kPabsP>-0.001916</kPabsP>
                <kP>-1</kP>
                <mQabsQ>-6.32698957</mQabsQ>
                <mQ>-1</mQ>
                <nRabsR>-6.32698957</nRabsR>
                <nR>-1</nR>
            </plugin>
                        <!-- Thruster plugin -->
            <plugin
                filename="ignition-gazebo-thruster-system"
                name="ignition::gazebo::systems::Thruster">
                <joint_name>joint_propeller_port_L</joint_name>
                <namespace>box_usv</namespace>
                <topic>thruster_L</topic>
                <thrust_coefficient>0.001</thrust_coefficient>
                <fluid_density>1000</fluid_density>
                <propeller_diameter>0.4</propeller_diameter>
            </plugin>
            <plugin
                filename="ignition-gazebo-thruster-system"
                name="ignition::gazebo::systems::Thruster">
                <joint_name>joint_propeller_port_R</joint_name>
                <namespace>box_usv</namespace>
                <topic>thruster_R</topic>
                <thrust_coefficient>0.001</thrust_coefficient>
                <fluid_density>1000</fluid_density>
                <propeller_diameter>0.4</propeller_diameter>
            </plugin>
            <!-- <plugin filename="ignition-gazebo-camera-system"
                    name="ignition::gazebo::systems::CameraSensor">
            </plugin> -->
            <plugin
            filename="ignition-gazebo-sensors-system"
            name="ignition::gazebo::systems::Sensors">
            <render_engine>ogre2</render_engine>
            </plugin>
        </model>
    </world>
</sdf>